2021-08-17 23:19:18,149 ERROR: error website
2021-08-17 23:23:39,311 ERROR: error output
2021-09-01 23:53:56,215 ERROR: Http Error:404 Client Error: Not Found for url: http://www.google.com/blahblah
2021-09-01 23:54:25,923 ERROR: Http Error:404 Client Error: Not Found for url: http://www.google.com/blahblah
2021-09-02 00:23:09,010 ERROR: HTTPError 404 Client Error: Not Found for url: http://www.google.com/blahblah
2021-09-02 00:23:38,127 ERROR: HTTPError：404 Client Error: Not Found for url: http://www.google.com/blahblah
2021-09-02 00:24:09,306 ERROR: HTTPError:404 Client Error: Not Found for url: http://www.google.com/blahblah
2021-09-02 00:35:56,430 ERROR: HTTPError: 404 Client Error: Not Found for url: http://www.google.com/blahblah
2021-09-02 00:36:07,164 ERROR: HTTPError: 404 Client Error: Not Found for url: http://www.google.com/blahblah
2021-09-02 00:37:08,246 ERROR: ValueError: invalid literal for int() with base 10: 'q'
2021-09-02 00:51:06,544 ERROR: HTTPError: 404 Client Error: Not Found for url: http://www.google.com/blahblah
2021-09-05 20:04:04,506 ERROR: ValueError: invalid literal for int() with base 10: '.'
2021-09-08 23:24:04,776 ERROR: ValueError: invalid literal for int() with base 10: 'q'
2021-09-08 23:28:37,198 ERROR: error condition
2021-09-08 23:31:24,032 ERROR: condition_1 out of range
2021-09-08 23:39:46,767 ERROR: UnboundLocalError: local variable 'rp' referenced before assignment
2021-09-08 23:54:30,345 ERROR: condition_1 out of range
2021-09-08 23:56:33,614 ERROR: TypeError: can only concatenate str (not "int") to str
2021-09-09 00:46:09,575 ERROR: ZeroDivisionError: division by zero
2021-09-09 00:46:09,699 ERROR: ZeroDivisionError: division by zero
2021-09-09 00:46:09,832 ERROR: ZeroDivisionError: division by zero
2021-09-09 00:46:10,678 ERROR: ZeroDivisionError: division by zero
2021-09-09 00:46:10,801 ERROR: ZeroDivisionError: division by zero
2021-09-09 00:46:10,920 ERROR: ZeroDivisionError: division by zero
2021-09-09 00:46:11,086 ERROR: ZeroDivisionError: division by zero
2021-09-09 00:46:11,258 ERROR: ZeroDivisionError: division by zero
2021-09-09 00:46:11,371 ERROR: ZeroDivisionError: division by zero
2021-09-10 10:52:24,222 ERROR: ZeroDivisionError: division by zero
2021-09-10 10:52:39,095 ERROR: ZeroDivisionError: division by zero
2021-09-10 10:56:03,085 ERROR: ZeroDivisionError: division by zero
2021-09-10 10:56:03,085 ERROR: ZeroDivisionError: division by zero
2021-09-10 11:12:05,880 ERROR: ZeroDivisionError: division by zero
2021-09-10 13:42:26,987 ERROR: TypeError: object of type 'NoneType' has no len()
2021-09-14 02:01:49,511 ERROR: condition_1 out of range
2021-09-14 06:46:23,915 ERROR: File "C:\Users\User\Desktop\7F\def.py", line 490, in main: [ZeroDivisionError] division by zero
2021-09-14 06:47:49,021 ERROR: File "C:\Users\User\Desktop\7F\def.py", line 120, in front_page_url: [ZeroDivisionError] division by zero
2021-09-27 17:45:22,536 ERROR: File "D:\miniconda\envs\7F\lib\site-packages\requests\models.py", line 390, in prepare_url: [MissingSchema] Invalid URL 'www.ee.ncku.edu.tw': No schema supplied. Perhaps you meant http://www.ee.ncku.edu.tw?
2021-09-27 17:45:47,633 ERROR: File "C:\Users\User\Desktop\7F\個資掃描工具_v2.0.py", line 416, in reg_find: [UnboundLocalError] local variable 'phone_str' referenced before assignment
2021-09-29 01:20:28,804 ERROR: File "D:\miniconda\envs\7F\lib\site-packages\pandas\io\common.py", line 647, in get_handle: [PermissionError] 13
2021-09-29 01:20:45,920 ERROR: File "D:\miniconda\envs\7F\lib\site-packages\requests\adapters.py", line 529, in send: [ReadTimeout] HTTPSConnectionPool(host='www.bsps.tn.edu.tw', port=443): Read timed out. (read timeout=3)
2021-09-29 01:32:19,578 ERROR: File "D:\miniconda\envs\7F\lib\site-packages\pandas\io\common.py", line 647, in get_handle: [PermissionError] 13
2021-09-29 15:17:13,067 ERROR: File "D:\miniconda\envs\7F\lib\site-packages\requests\models.py", line 390, in prepare_url: [MissingSchema] Invalid URL 'www.stust.edu.tw': No schema supplied. Perhaps you meant http://www.stust.edu.tw?
2021-10-04 20:33:59,544 ERROR: File "D:\miniconda\envs\7F\lib\site-packages\pandas\io\common.py", line 647, in get_handle: [PermissionError] 13
2021-10-04 20:35:28,119 ERROR: File "D:\miniconda\envs\7F\lib\site-packages\pandas\io\common.py", line 647, in get_handle: [PermissionError] 13
2021-10-04 20:51:28,666 ERROR: File "D:\miniconda\envs\7F\lib\site-packages\pandas\io\common.py", line 647, in get_handle: [PermissionError] 13
2021-10-04 21:33:28,640 ERROR: condition_3 out of range
2021-10-04 21:34:21,704 ERROR: File "D:\miniconda\envs\7F\lib\site-packages\requests\sessions.py", line 742, in get_adapter: [InvalidSchema] No connection adapters were found for 'try:'
2021-10-05 04:47:01,130 ERROR: File "D:\miniconda\envs\7F\lib\site-packages\pandas\io\common.py", line 647, in get_handle: [PermissionError] 13
2021-10-05 04:49:14,977 ERROR: File "D:\miniconda\envs\7F\lib\site-packages\pandas\io\common.py", line 647, in get_handle: [PermissionError] 13
2021-10-05 04:52:17,316 ERROR: File "D:\miniconda\envs\7F\lib\site-packages\pandas\io\common.py", line 647, in get_handle: [PermissionError] 13
2021-10-05 04:52:59,135 ERROR: File "D:\miniconda\envs\7F\lib\site-packages\pandas\io\common.py", line 647, in get_handle: [PermissionError] 13
2021-10-18 17:22:41,461 ERROR: File "D:\miniconda\envs\7F\lib\site-packages\requests\models.py", line 390, in prepare_url: [MissingSchema] Invalid URL '1': No schema supplied. Perhaps you meant http://1?
2021-10-18 17:39:06,406 ERROR: File "D:\miniconda\envs\7F\lib\site-packages\requests\models.py", line 390, in prepare_url: [MissingSchema] Invalid URL '': No schema supplied. Perhaps you meant http://?
2021-10-18 17:39:27,409 ERROR: File "C:\Users\User\Desktop\7F\個資掃描工具_v2.1.py", line 642, in main: [TypeError] __init__() missing 1 required positional argument: 'condition_arr'
2021-10-18 18:19:06,257 ERROR: File "C:\Users\User\Desktop\7F\個資掃描工具_v2.1.py", line 195, in get_url: [NameError] name 'qqq' is not defined
2021-11-12 01:37:39,140 ERROR: File "C:\Users\User\Desktop\7F\Personal-Information-Scanner.py", line 468, in reg_find: [AttributeError] 'Analysis' object has no attribute 'r_name_check'
2021-11-12 01:44:33,702 ERROR: File "C:\Users\User\Desktop\7F\Personal-Information-Scanner.py", line 568, in name_check: [UnicodeDecodeError] cp950
2021-11-12 01:45:17,013 ERROR: File "C:\Users\User\Desktop\7F\Personal-Information-Scanner.py", line 568, in name_check: [UnicodeDecodeError] cp950
2021-11-12 01:46:27,553 ERROR: File "C:\Users\User\Desktop\7F\Personal-Information-Scanner.py", line 568, in name_check: [UnicodeDecodeError] cp950
2021-11-12 02:08:25,102 ERROR: File "D:\miniconda\envs\7F\lib\site-packages\requests\models.py", line 390, in prepare_url: [MissingSchema] Invalid URL '1': No schema supplied. Perhaps you meant http://1?
2021-11-12 04:23:32,955 ERROR: File "C:\Users\User\Desktop\7F\Personal-Information-Scanner.py", line 178, in get_url: [IndexError] string index out of range
2021-11-12 04:23:58,220 ERROR: File "C:\Users\User\Desktop\7F\Personal-Information-Scanner.py", line 178, in get_url: [IndexError] string index out of range
2021-11-17 11:44:10,235 ERROR: File "C:\Users\User\Desktop\7F\Personal-Information-Scanner.py", line 581, in name_check: [UnicodeDecodeError] cp950
2021-11-24 23:50:05,686 ERROR: File "C:\Users\User\Desktop\7F\Personal-Information-Scanner.py", line 584, in reg_find: [ValueError] not enough values to unpack (expected 3, got 0)
2021-11-30 02:01:17,196 ERROR: File "D:\miniconda\envs\7F\lib\site-packages\requests\adapters.py", line 529, in send: [ReadTimeout] HTTPSConnectionPool(host='depart.moe.edu.tw', port=443): Read timed out. (read timeout=3)
